<?xml version="1.0" ?>
<robot name="isci_robot" xmlns:xacro="http://www.ros.org/wiki/xacro">
  
  <link name="base_link" /> 
    
  <link name="link_chassis">
    <!-- pose and inertial -->
    <inertial>
      <mass value="50"/>
      <origin rpy="0 0 0" xyz="0 0 0"/>
      <inertia
        ixx="0.774276574699151"
        ixy="-1.03781944357671E-10"
        ixz="0.00763014265820928"
        iyy="1.64933255189991"
        iyz="1.09578155845563E-12"
        izz="2.1239326987473" />
    </inertial>
    <!-- body -->
    <!-- <collision name="collision_chassis">
      <origin rpy="0 0 0" xyz="0 0 0"/>
      <geometry>
        <box size="0.8 0.5 0.68"/>
      </geometry>
    </collision> -->
    <visual>
      <origin rpy="0 0 0" xyz="0 0 0"/>
      <geometry>
        <box size="0.8 0.5 0.68"/>
      </geometry>
      <material name="">
          <color rgba="0.79216 0.81961 0.93333 1" />
      </material>
    </visual>   
  </link>

  <joint name="base_link_joint" type="fixed">
    <parent link="base_link"/>
    <child link="link_chassis" />
    <origin xyz="0 0 0.51" rpy="0 0 0"/>
  </joint>
  
  <link name="caster_front">
    <!-- pose and inertial -->
    <inertial>
      <mass value="1"/>
      <origin rpy="0 0 0" xyz="0 0 0"/>
      <inertia
        ixx="0.00856502765719703"
        ixy="1.5074118157338E-19"
        ixz="-4.78150098725052E-19"
        iyy="0.013670640432096"
        iyz="-2.68136447099727E-19"
        izz="0.00856502765719703" />
    </inertial>
    <collision name="caster_front_collision">
      <origin rpy=" 0 0 0" xyz="0 0 0"/>
      <geometry>
        <sphere radius="0.08"/>
      </geometry>
    </collision>
    <visual name="caster_front_visual">
      <origin rpy=" 0 0 0" xyz="0 0 0"/>
      <geometry>
        <sphere radius="0.08"/>
      </geometry>
    </visual>
  </link>

  <joint name="bottom2caster_front_joint" type="fixed">
    <parent link="link_chassis"/>
    <child link="caster_front" />
    <origin xyz="0.3 0 -0.43" rpy="0 0 0"/>
  </joint>

  <link name="caster_back">
    <!-- pose and inertial -->
    <inertial>
      <mass value="1"/>
      <origin rpy="0 0 0" xyz="0 0 0"/>
      <inertia
        ixx="0.00856502765719703"
        ixy="1.5074118157338E-19"
        ixz="-4.78150098725052E-19"
        iyy="0.013670640432096"
        iyz="-2.68136447099727E-19"
        izz="0.00856502765719703" />
    </inertial>
    <collision name="caster_back_collision">
      <origin rpy=" 0 0 0" xyz="0 0 0"/>
      <geometry>
        <sphere radius="0.08"/>
      </geometry>
    </collision>
    <visual name="caster_back_visual">
      <origin rpy=" 0 0 0" xyz="0 0 0"/>
      <geometry>
        <sphere radius="0.08"/>
      </geometry>
    </visual>
  </link>

  <joint name="bottom2caster_back_joint" type="fixed">
    <parent link="link_chassis"/>
    <child link="caster_back" />
    <origin xyz="-0.3 0 -0.43" rpy="0 0 0"/>
  </joint>

  <link name="link_right_wheel">
    <inertial>
      <origin xyz="0 0 0" />
      <mass value="2.6578" />
      <inertia
        ixx="0.00856502765719703"
        ixy="1.5074118157338E-19"
        ixz="-4.78150098725052E-19"
        iyy="0.013670640432096"
        iyz="-2.68136447099727E-19"
        izz="0.00856502765719703" />
      </inertial>
    <collision name="link_right_wheel_collision">
      <origin rpy="0 1.5707 1.5707" xyz="0 0 0"/>
      <geometry>
        <cylinder length="0.04" radius="0.08"/>
      </geometry>
    </collision>
    <visual name="link_right_wheel_visual">
      <origin rpy="0 1.5707 1.5707" xyz="0 0 0"/>
      <geometry>
        <cylinder length="0.04" radius="0.08"/>
      </geometry>
      <material name="">
        <color rgba="0.79216 0.81961 0.93333 1" />
      </material>
    </visual>
  </link>
  
  <joint name="joint_right_wheel" type="continuous">
    <origin rpy="0 0 0" xyz="0 0.25 -0.43"/>
    <child link="link_right_wheel"/>
    <parent link="link_chassis"/>
    <axis rpy="0 0 0" xyz="0 1 0"/>

    <dynamics damping="0.5"/>
    <limit effort="10" velocity="20"/>
  </joint>
  
  <link name="link_left_wheel">
    <inertial>
      <origin xyz="0 0 0" />
      <mass value="2.6578" />
      <inertia
        ixx="0.00856502765719703"
        ixy="1.5074118157338E-19"
        ixz="-4.78150098725052E-19"
        iyy="0.013670640432096"
        iyz="-2.68136447099727E-19"
        izz="0.00856502765719703" />
      </inertial>
    <collision name="link_left_wheel_collision">
      <origin rpy="0 1.5707 1.5707" xyz="0 0 0"/>
      <geometry>
        <cylinder length="0.04" radius="0.08"/>
      </geometry>
    </collision>
    <visual name="link_left_wheel_visual">
      <origin rpy="0 1.5707 1.5707" xyz="0 0 0"/>
      <geometry>
        <cylinder length="0.04" radius="0.08"/>
      </geometry>
      <material name="LightGrey">
        <color rgba="0.7 0.7 0.7 1.0"/>
      </material>
    </visual>
  </link>
  
  <joint name="joint_left_wheel" type="continuous">
    <origin rpy="0 0 0" xyz="0 -0.25 -0.43"/>
    <child link="link_left_wheel"/>
    <parent link="link_chassis"/>
    <axis rpy="0 0 0" xyz="0 1 0"/>

    <dynamics damping="0.5"/>
    <limit effort="10" velocity="20"/>
  </joint>


  <!--******************* add Velodyne Link ********************************-->
  <link name="VLP16_base_link">
  </link>

  <joint name="VLP16_base_mount_joint" type="fixed">
    <origin xyz="0.0 0 0.3823" rpy="0 -0.17444 0"/>
    <child link="VLP16_base_link"/>
    <parent link="link_chassis"/>
  </joint>   

  <xacro:include filename="$(find velodyne_description)/urdf/VLP-16.urdf.xacro"/>
  <xacro:VLP-16 parent="VLP16_base_link" name="velodyne" topic="/velodyne_points" hz="10" samples="1000" >
    <origin xyz="0 0.0 0.0" rpy="0 0 0" />
  </xacro:VLP-16>

  <!--******************* add TM5 Link *************************************-->
  <link name="link_0">
        <visual>
            <geometry>
                <mesh filename="package://isci_robot/urdf/isci_tmr/meshes/tm5-900/visual/tm5_base.obj" />
            </geometry>
            <!-- <material name="link_0" /> -->
        </visual>
        <collision>
            <geometry>
                <mesh filename="package://isci_robot/urdf/isci_tmr/meshes/tm5-900/collision/tm5_base_c.stl" />
            </geometry>
        </collision>
        <inertial>
            <mass value="1.0" />
            <origin rpy="0 0 0" xyz="0 0 0" />
            <inertia ixx="0.00110833289" ixy="0.0" ixz="0.0" iyy="0.00110833289" iyz="0.0" izz="0.0018" />
        </inertial>
    </link>
    <joint name="shoulder_1_joint" type="revolute">
        <parent link="link_0" />
        <child link="link_1" />
        <origin rpy="0 0 0" xyz="0 0 0.1452" />
        <axis xyz="0 0 1" />
        <!--limit-->
        <limit effort="320.0" lower="-4.71238898038" upper="4.71238898038" velocity="3.14" />
    </joint>
    <link name="link_1">
        <visual>
            <geometry>
                <mesh filename="package://isci_robot/urdf/isci_tmr/meshes/tm5-900/visual/tmr_400w_01.obj" />
            </geometry>
            <!-- <material name="link_1" /> -->
        </visual>
        <collision>
            <geometry>
                <mesh filename="package://isci_robot/urdf/isci_tmr/meshes/tm5-900/collision/tmr_400w_01_c.stl" />
            </geometry>
        </collision>
        <inertial>
            <mass value="4.5" />
            <origin rpy="0 0 0" xyz="0 0 0" />
            <inertia ixx="0.012487495005" ixy="0.0" ixz="0.0" iyy="0.012487495005" iyz="0.0" izz="0.0081" />
        </inertial>
    </link>
    <joint name="shoulder_2_joint" type="revolute">
        <parent link="link_1" />
        <child link="link_2" />
        <origin rpy="-1.57079632679 -1.57079632679 0" xyz="0 0 0" />
        <axis xyz="0 0 1" />
        <!--limit-->
        <limit effort="320" lower="-3.14159265359" upper="3.14159265359" velocity="3.14" />
    </joint>
    <link name="link_2">
        <visual>
            <geometry>
                <mesh filename="package://isci_robot/urdf/isci_tmr/meshes/tm5-900/visual/tm5-900_arm1.obj" />
            </geometry>
            <!-- <material name="link_2" /> -->
        </visual>
        <collision>
            <geometry>
                <mesh filename="package://isci_robot/urdf/isci_tmr/meshes/tm5-900/collision/tm5-900_arm1_c.stl" />
            </geometry>
        </collision>
        <inertial>
            <mass value="11.0" />
            <origin rpy="0 0 0" xyz="0.2145 0 -0.146" />
            <inertia ixx="0.0198" ixy="0.0" ixz="0.0" iyy="0.178604178558" iyz="0.0" izz="0.178604178558" />
        </inertial>
    </link>
    <joint name="elbow_joint" type="revolute">
        <parent link="link_2" />
        <child link="link_3" />
        <origin rpy="0 0 0" xyz="0.429 0 0" />
        <axis xyz="0 0 1" />
        <!--limit-->
        <limit effort="320" lower="-3.14159265359" upper="3.14159265359" velocity="3.14" />
    </joint>
    <link name="link_3">
        <visual>
            <geometry>
                <mesh filename="package://isci_robot/urdf/isci_tmr/meshes/tm5-900/visual/tm5-900_arm2.obj" />
            </geometry>
            <!-- <material name="link_3" /> -->
        </visual>
        <collision>
            <geometry>
                <mesh filename="package://isci_robot/urdf/isci_tmr/meshes/tm5-900/collision/tm5-900_arm2_c.stl" />
            </geometry>
        </collision>
        <inertial>
            <mass value="2.5" />
            <origin rpy="0 0 0" xyz="0.20575 0 -0.0163" />
            <inertia ixx="0.00253125" ixy="0.0" ixz="0.0" iyy="0.0365431624661" iyz="0.0" izz="0.0365431624661" />
        </inertial>
    </link>
    <joint name="wrist_1_joint" type="revolute">
        <parent link="link_3" />
        <child link="link_4" />
        <origin rpy="0 0 1.57079632679" xyz="0.4115 0 -0.1223" />
        <axis xyz="0 0 1" />
        <!--limit-->
        <limit effort="80" lower="-3.14159265359" upper="3.14159265359" velocity="3.92" />
    </joint>
    <link name="link_4">
        <visual>
            <geometry>
                <mesh filename="package://isci_robot/urdf/isci_tmr/meshes/tm5-900/visual/tmr_100w_01.obj" />
            </geometry>
            <!-- <material name="link_4" /> -->
        </visual>
        <collision>
            <geometry>
                <mesh filename="package://isci_robot/urdf/isci_tmr/meshes/tm5-900/collision/tmr_100w_01_c.stl" />
            </geometry>
        </collision>
        <inertial>
            <mass value="1.45" />
            <origin rpy="0 0 0" xyz="0 0 0" />
            <inertia ixx="0.00247406151038" ixy="0.0" ixz="0.0" iyy="0.001468125" iyz="0.0" izz="0.00247406151038" />
        </inertial>
    </link>
    <joint name="wrist_2_joint" type="revolute">
        <parent link="link_4" />
        <child link="link_5" />
        <origin rpy="1.57079632679 0 0" xyz="0 -0.106 0" />
        <axis xyz="0 0 1" />
        <!--limit-->
        <limit effort="80" lower="-3.14159265359" upper="3.14159265359" velocity="3.92" />
    </joint>
    <link name="link_5">
        <visual>
            <geometry>
                <mesh filename="package://isci_robot/urdf/isci_tmr/meshes/tm5-900/visual/tmr_100w_02.obj" />
            </geometry>
            <!-- <material name="link_5" /> -->
        </visual>
        <collision>
            <geometry>
                <mesh filename="package://isci_robot/urdf/isci_tmr/meshes/tm5-900/collision/tmr_100w_02_c.stl" />
            </geometry>
        </collision>
        <inertial>
            <mass value="1.45" />
            <origin rpy="0 0 0" xyz="0 0 0" />
            <inertia ixx="0.00247406151038" ixy="0.0" ixz="0.0" iyy="0.001468125" iyz="0.0" izz="0.00247406151038" />
        </inertial>
    </link>
    <joint name="wrist_3_joint" type="revolute">
        <parent link="link_5" />
        <child link="link_6" />
        <origin rpy="1.57079632679 0 0" xyz="0 -0.11315 0" />
        <axis xyz="0 0 1" />
        <!--limit-->
        <limit effort="80" lower="-4.71238898038" upper="4.71238898038" velocity="3.92" />
    </joint>
    <link name="link_6">
        <visual>
            <geometry>
                <mesh filename="package://isci_robot/urdf/isci_tmr/meshes/tm5-900/visual/tmr_ee.obj" />
            </geometry>
            <!-- <material name="link_6" /> -->
        </visual>
        <collision>
            <geometry>
                <mesh filename="package://isci_robot/urdf/isci_tmr/meshes/tm5-900/collision/tmr_ee_c.stl" />
            </geometry>
        </collision>
        <inertial>
            <mass value="0.4" />
            <origin rpy="0 0 0" xyz="0 0 0" />
            <inertia ixx="0.000322499871" ixy="0.0" ixz="0.0" iyy="0.000322499871" iyz="0.0" izz="0.000405" />
        </inertial>
    </link>

    <link name="mid_mount"/>
    <joint name="mid_mount_joint" type="fixed">
      <parent link="link_chassis"/>
      <child link="mid_mount"/>
      <origin rpy="0 0 0" xyz="-0.2 0.0 0.34"/>
    </joint>
    
    <joint name="arm_mount_joint" type="fixed">
      <parent link="mid_mount"/>
      <child link="base"/>
      <origin rpy="0 0 0" xyz="0 0 0"/>
    </joint>

    <link name="base" />
    <joint name="base_fixed_joint" type="fixed">
        <parent link="base" />
        <child link="link_0" />
        <origin rpy="0 0 0" xyz="0 0 0" />
    </joint>
    <link name="flange" />
    <joint name="flange_fixed_joint" type="fixed">
        <parent link="link_6" />
        <child link="flange" />
        <origin rpy="0 0 0" xyz="0 0 0" />
    </joint>
  
  <link name="tool0"/>
  <joint name="flange_link-tool0" type="fixed">
    <parent link="flange"/>
    <child link="tool0"/>
    <origin rpy="0.000000 0.000000 0.000000" xyz="0.000000 0.000000 0.000000"/>
  </joint>
  
  <!--########################## BASE TRANSMISSIONS ############################################-->
  <transmission name="left_wheel_trans" type="SimpleTransmission">
  <type>transmission_interface/SimpleTransmission</type>
  <actuator name="left_wheel_motor">
   <hardwareInterface>hardware_interface/VelocityJointInterface</hardwareInterface>
   <mechanicalReduction>1</mechanicalReduction>
  </actuator>
  <joint name="joint_left_wheel">
   <hardwareInterface>hardware_interface/VelocityJointInterface</hardwareInterface>
  </joint>
  </transmission>

  <transmission name="right_wheel_trans" type="SimpleTransmission">
    <type>transmission_interface/SimpleTransmission</type>
    <actuator name="right_wheel_motor">
    <hardwareInterface>hardware_interface/VelocityJointInterface</hardwareInterface>
    <mechanicalReduction>1</mechanicalReduction>
    </actuator>
    <joint name="joint_right_wheel">
    <hardwareInterface>hardware_interface/VelocityJointInterface</hardwareInterface>
    </joint>
  </transmission>
<!--################################ ARM TRANSIMISSIONS ######################################-->
  <transmission name="arm_base_trans" type="SimpleTransmission">
    <type>transmission_interface/SimpleTransmission</type>
    <actuator name="arm_base_motor">
    <hardwareInterface>hardware_interface/VelocityJointInterface</hardwareInterface>
    <mechanicalReduction>1</mechanicalReduction>
    </actuator>
    <joint name="shoulder_1_joint">
    <hardwareInterface>hardware_interface/VelocityJointInterface</hardwareInterface>
    <dynamics damping="10" friction="0.1"/>
    </joint>
  </transmission>

  <transmission name="shoulder_trans" type="SimpleTransmission">
    <type>transmission_interface/SimpleTransmission</type>
    <actuator name="shoulder_motor">
    <hardwareInterface>hardware_interface/VelocityJointInterface</hardwareInterface>
    <mechanicalReduction>1</mechanicalReduction>
    </actuator>
    <joint name="shoulder_2_joint">
    <hardwareInterface>hardware_interface/VelocityJointInterface</hardwareInterface>
    </joint>
  </transmission>

  <transmission name="bottom_wrist_trans" type="SimpleTransmission">
    <type>transmission_interface/SimpleTransmission</type>
    <actuator name="bottom_wrist_motor">
    <hardwareInterface>hardware_interface/VelocityJointInterface</hardwareInterface>
    <mechanicalReduction>1</mechanicalReduction>
    </actuator>
    <joint name="elbow_joint">
    <hardwareInterface>hardware_interface/VelocityJointInterface</hardwareInterface>
    </joint>
  </transmission>

  <transmission name="elbow_trans" type="SimpleTransmission">
    <type>transmission_interface/SimpleTransmission</type>
    <actuator name="elbow_motor">
    <hardwareInterface>hardware_interface/VelocityJointInterface</hardwareInterface>
    <mechanicalReduction>1</mechanicalReduction>
    </actuator>
    <joint name="wrist_1_joint">
    <hardwareInterface>hardware_interface/VelocityJointInterface</hardwareInterface>
    </joint>
  </transmission>

  <transmission name="top_wrist_trans" type="SimpleTransmission">
    <type>transmission_interface/SimpleTransmission</type>
    <actuator name="top_wrist_motor">
    <hardwareInterface>hardware_interface/VelocityJointInterface</hardwareInterface>
    <mechanicalReduction>1</mechanicalReduction>
    </actuator>
    <joint name="wrist_2_joint">
    <hardwareInterface>hardware_interface/VelocityJointInterface</hardwareInterface>
    </joint>
  </transmission>

  <transmission name="top_wrist_3_trans" type="SimpleTransmission">
    <type>transmission_interface/SimpleTransmission</type>
    <actuator name="top_wrist_motor2">
    <hardwareInterface>hardware_interface/VelocityJointInterface</hardwareInterface>
    <mechanicalReduction>1</mechanicalReduction>
    </actuator>
    <joint name="wrist_3_joint">
    <hardwareInterface>hardware_interface/VelocityJointInterface</hardwareInterface>
    </joint>
  </transmission>
<!--######################################################################-->
  <gazebo>
    
    <plugin name="gazebo_ros_control" filename="libgazebo_ros_control.so">/
      <legacyModeNS>true</legacyModeNS>
      <robotSimType>gazebo_ros_control/DefaultRobotHWSim</robotSimType>
    </plugin>

    <!-- <plugin name="joint_state_publisher" filename="libgazebo_ros_joint_state_publisher.so">
      <jointName>shoulder_1_joint, shoulder_2_joint, elbow_joint, wrist_1_joint, wrist_2_joint,wrist_3_joint</jointName>
    </plugin> -->

    <!-- <plugin name="gazebo_ros_control_select_joints" filename="libgazebo_ros_control_select_joints.so">
      <legacyModeNS>true</legacyModeNS>
      <jointName>shoulder_1_joint, shoulder_2_joint, elbow_joint, wrist_1_joint, wrist_2_joint,wrist_3_joint</jointName>
      <robotSimType>gazebo_ros_control/DefaultRobotHWSim</robotSimType>
    </plugin> -->
  </gazebo>

<!--######################################################################-->
  <gazebo>
    <plugin name="diff_drive_controller" filename="libgazebo_ros_diff_drive.so">
      <alwaysOn>true</alwaysOn>
      <updateRate>100.0</updateRate>
      <leftJoint>joint_right_wheel</leftJoint>
      <rightJoint>joint_left_wheel</rightJoint>
      <wheelSeparation>0.5</wheelSeparation>
      <wheelDiameter>0.16</wheelDiameter>
      <publishTf>true</publishTf>
      <odometryFrame>odom</odometryFrame>
      <commandTopic>cmd_vel</commandTopic>
      <odometryTopic>odom</odometryTopic>
      <robotBaseFrame>base_link</robotBaseFrame>
      <wheelAcceleration>3.0</wheelAcceleration>
      <wheelTorque>30</wheelTorque>
      <publishWheelJointState>false</publishWheelJointState>
      <publishWheelTF>false</publishWheelTF>
      <odometrySource>world</odometrySource>
      <rosDebugLevel>Debug</rosDebugLevel>
      <publishOdomTF>true</publishOdomTF>
    </plugin>
  </gazebo>
<!--######################################################################-->

  <gazebo reference="link_chassis">
    <material>Gazebo/Orange</material>
  </gazebo>
  <gazebo reference="link_left_wheel">
    <material>Gazebo/Blue</material>
  </gazebo>
  <gazebo reference="link_right_wheel">
    <material>Gazebo/Blue</material>
  </gazebo>

  <gazebo reference="caster_front">
    <mu1>0.00001</mu1>
    <mu2>0.00001</mu2>
    <material>Gazebo/White</material>
  </gazebo>
  <gazebo reference="caster_back">
    <mu1>0.00001</mu1>
    <mu2>0.00001</mu2>
    <material>Gazebo/White</material>
  </gazebo>

  <gazebo reference="link_1">
      <selfCollide>true</selfCollide>
  </gazebo>
  <gazebo reference="link_2">
      <selfCollide>true</selfCollide>
  </gazebo>
  <gazebo reference="link_3">
      <selfCollide>true</selfCollide>
  </gazebo>
  <gazebo reference="link_4">
      <selfCollide>true</selfCollide>
  </gazebo>
  <gazebo reference="link_5">
      <selfCollide>true</selfCollide>
  </gazebo>
  <gazebo reference="link_6">
      <selfCollide>true</selfCollide>
  </gazebo>

  <material name="grey">
      <color rgba="0.5 0.5 0.5 1.0" />
  </material>
  <material name="white">
      <color rgba="0.95 0.95 0.95 1.0" />
  </material>
  <material name="red">
      <color rgba="0.95 0.0 0.0 1.0" />
  </material>
  <material name="orange">
      <color rgba="1.0 0.5 0.0 1.0" />
  </material>
  <material name="yellow">
      <color rgba="1.0 1.0 0.0 1.0" />
  </material>
  <material name="green">
      <color rgba="0.0 1.0 0.0 1.0" />
  </material>
  <material name="blue">
      <color rgba="0.0 0.0 1.0 1.0" />
  </material>
  <material name="indigo">
      <color rgba="0.3 0.3 0.6 1.0" />
  </material>
  <material name="violet">
      <color rgba="0.6 0.0 1.0 1.0" />
  </material>
  <material name="black">
      <color rgba="0.0 0.0 0.0 1.0" />
  </material>

  <gazebo reference="link_1">
    <gravity>0</gravity>
    <turnGravityOff>1</turnGravityOff>
  </gazebo>
  <gazebo reference="link_2">
    <gravity>0</gravity>
    <turnGravityOff>1</turnGravityOff>
  </gazebo>
  <gazebo reference="link_3">
    <gravity>0</gravity>
    <turnGravityOff>1</turnGravityOff>
  </gazebo>
  <gazebo reference="link_4">
    <gravity>0</gravity>
    <turnGravityOff>1</turnGravityOff>
  </gazebo>
  <gazebo reference="link_5">
    <gravity>0</gravity>
    <turnGravityOff>1</turnGravityOff>
  </gazebo>
  <gazebo reference="link_6">
    <gravity>0</gravity>
    <turnGravityOff>1</turnGravityOff>
  </gazebo>
  
</robot>